Workbook
Name Slicer_Category1: #N/A
Name Slicer_Expense_Amount: #N/A
Name Slicer_Expense_Category: #N/A
Name Slicer_Income_Source: #N/A
Name Slicer_Month: #N/A

Sheet Welcome Page
C2: 💰 PERSONAL FINANCE & BUDGET PLANNER
C5: -------EXECUTIVE DASHBOARD & FINANCIAL ANALYTICS SYSTEM-------
C9: WELCOME | J9: Project Name | M9: Personal Finance & Budget Planner | S9: “Do not save what is left after spending, spend what is left after saving.” — Warren Buffett
J11: Developed By | M11: Abhijit Roy & Aakash Nath
C13: •Track • Analyze • Save • Grow | J13: Technology | M13: Microsoft Excel
J15: Features | M15: KPI Dashboard, Pivot Analysis, Budget Tracking & Insights
J17: Academic Year | M17: 2026
J19: Institute | M19: Anudip Foundation, COE
C22: START DASHBOARD | F22: VIEW RAW DATA | J22: INCOME ANALYSIS | M22: EXPENSE ANALYSIS | P22: PIVOT ANALYSIS
C27: © 2025 Personal Finance & Budget Planner | Developed using Microsoft Excel 🗝️

Sheet Raw Data
A1: RAW DATA | O1: Go to Welcome Page
A2: Id | B2: Date | C2: Month | D2: Person Name | E2: Age | F2: City | G2: Income Source | H2: Monthly Income | I2: ExpenseCategory | J2: Expense Amount | K2: Payment Method | L2: Savings | M2: Loan EMI | N2: Credit Score | O2: Financial Status
A3: TXN1001 | B3: 45659 | C3: January | D3: Rahul Sen | E3: 29 | F3: Kolkata | G3: Salary | H3: 65000 | I3: Rent | J3: 18000 | K3: UPI | L3: 12000 | M3: 5000 | N3: 742 | O3: Stable
A4: TXN1002 | B4: 45660 | C4: February | D4: Priya Das | E4: 34 | F4: Mumbai | G4: Freelancing | H4: 72000 | I4: Groceries | J4: 6500 | K4: Card | L4: 15000 | N4: 788 | O4: Good
A5: TXN1003 | B5: 45661 | C5: March | D5: Ankit Roy | E5: 26 | G5: Salary | H5: 54000 | J5: 3200 | K5: Cash | L5: 8000 | M5: 2500 | N5: 689 | O5: Average
A6: TXN1004 | B6: 45662 | C6: April | D6: Sneha Paul | E6: 31 | F6: Bangalore | G6: Business | H6: 98000 | I6: Utilities | J6: 5400 | K6: NetBanking | L6: 25000 | M6: 8000 | N6: 801 | O6: Excellent
A7: TXN1005 | B7: 45663 | C7: May | D7: Rohan Mitra | E7: 38 | F7: Hyderabad | G7: Salary | H7: 85000 | I7: Entertainment | J7: 7600 | K7: Card | L7: 10000 | M7: 12000 | N7: 655 | O7: Risky
A8: TXN1006 | B8: 45664 | C8: June | D8: Aditi Sharma | E8: 27 | F8: Pune | H8: 61000 | I8: Healthcare | J8: 2400 | K8: UPI | L8: 17000 | N8: 771 | O8: Good
A9: TXN1007 | B9: 45665 | C9: July | D9: Karan Singh | E9: 42 | F9: Chennai | G9: Business | H9: 120000 | I9: Rent | J9: 25000 | K9: Cheque | L9: 35000 | M9: 18000 | N9: 720 | O9: Stable
A10: TXN1008 | B10: 45666 | C10: August | D10: Megha Dutta | E10: 24 | F10: Kolkata | G10: Internship | H10: 28000 | I10: Education | J10: 4500 | K10: UPI | L10: 5000 | N10: 690 | O10: Average
A11: TXN1009 | B11: 45667 | C11: September | D11: Arjun Nair | E11: 36 | F11: Kochi | G11: Salary | H11: 76000 | J11: 8200 | K11: Card | L11: 14000 | M11: 7000 | N11: 745 | O11: Stable
A12: TXN1010 | B12: 45668 | C12: October | D12: Neha Kapoor | E12: 30 | F12: Jaipur | G12: Freelancing | H12: 68000 | I12: Shopping | J12: 9200 | K12: UPI | L12: 11000 | M12: 3000 | N12: 732 | O12: Good
A13: TXN1011 | B13: 45669 | C13: November | D13: Vikram Bose | E13: 45 | F13: Kolkata | G13: Business | H13: 150000 | I13: Investment | J13: 35000 | K13: NetBanking | L13: 40000 | M13: 20000 | N13: 810 | O13: Excellent
A14: TXN1012 | B14: 45670 | C14: December | D14: Isha Jain | E14: 28 | F14: Delhi | H14: 59000 | I14: Food | J14: 5800 | L14: 9000 | M14: 2500 | N14: 704 | O14: Stable
A15: TXN1013 | B15: 45671 | C15: January | D15: Sourav Ghosh | E15: 33 | G15: Salary | H15: 71000 | I15: Rent | J15: 21000 | K15: UPI | L15: 13000 | M15: 6000 | N15: 740 | O15: Good
A16: TXN1014 | B16: 45672 | C16: February | D16: Ritika Sen | E16: 25 | F16: Pune | G16: Freelancing | H16: 47000 | I16: Entertainment | J16: 4200 | K16: Card | L16: 7000 | N16: 681 | O16: Average
A17: TXN1015 | B17: 45673 | C17: March | D17: Abhishek Das | E17: 39 | F17: Bangalore | G17: Business | H17: 132000 | I17: Healthcare | J17: 6800 | K17: NetBanking | L17: 30000 | M17: 15000 | N17: 790 | O17: Excellent
A18: TXN1016 | B18: 45674 | C18: April | D18: Nikita Roy | E18: 29 | F18: Delhi | G18: Salary | H18: 62000 | I18: Groceries | J18: 5900 | K18: UPI | L18: 12000 | M18: 3000 | N18: 725 | O18: Good
A19: TXN1017 | B19: 45675 | C19: May | D19: Manish Yadav | E19: 35 | F19: Mumbai | G19: Salary | H19: 81000 | I19: Transport | J19: 4100 | K19: Cash | L19: 16000 | M19: 9000 | N19: 710 | O19: Stable
A20: TXN1018 | B20: 45676 | C20: June | D20: Simran Kaur | E20: 27 | F20: Chandigarh | G20: Freelancing | H20: 56000 | J20: 9700 | K20: Card | L20: 8500 | N20: 699 | O20: Average
A21: TXN1019 | B21: 45677 | C21: July | D21: Raj Malhotra | E21: 41 | F21: Delhi | G21: Business | H21: 145000 | I21: Utilities | J21: 7800 | K21: Cheque | L21: 42000 | M21: 25000 | N21: 805 | O21: Excellent
A22: TXN1020 | B22: 45678 | C22: August | D22: Pooja Mehta | E22: 32 | F22: Ahmedabad | G22: Salary | H22: 69000 | I22: Food | J22: 6300 | K22: UPI | L22: 10000 | M22: 4500 | N22: 730 | O22: Good
A23: TXN1021 | B23: 45679 | C23: September | D23: Deepak Kumar | E23: 37 | F23: Patna | G23: Salary | H23: 57000 | I23: Rent | J23: 16000 | K23: Cash | L23: 6000 | M23: 5500 | N23: 670 | O23: Risky
A24: TXN1022 | B24: 45680 | C24: October | D24: Tanvi Shah | E24: 26 | F24: Surat | G24: Freelancing | H24: 52000 | I24: Shopping | J24: 7600 | K24: Card | L24: 9000 | N24: 715 | O24: Stable
A25: TXN1023 | B25: 45681 | C25: November | D25: Ritesh Verma | E25: 40 | H25: 125000 | I25: Investment | J25: 28000 | K25: NetBanking | L25: 37000 | M25: 12000 | N25: 798 | O25: Excellent
A26: TXN1024 | B26: 45682 | C26: December | D26: Ananya Ghosh | E26: 31 | F26: Kolkata | G26: Salary | H26: 74000 | I26: Education | J26: 5300 | K26: UPI | L26: 15000 | M26: 5000 | N26: 750 | O26: Good
A27: TXN1025 | B27: 45683 | C27: January | D27: Kunal Sharma | E27: 28 | F27: Delhi | G27: Salary | H27: 63000 | J27: 8600 | K27: Card | L27: 11000 | M27: 3500 | N27: 721 | O27: Stable
A28: TXN1075 | B28: 45733 | C28: February | D28: Amit Bose | E28: 36 | F28: Kolkata | G28: Salary | H28: 81000 | I28: Travel | J28: 9400 | K28: UPI | L28: 17000 | M28: 8500 | N28: 743 | O28: Good
A29: TXN1076 | B29: 45734 | C29: March | D29: Sonia Jain | E29: 27 | F29: Pune | G29: Freelancing | H29: 55000 | I29: Food | J29: 5200 | K29: Card | L29: 8000 | N29: 701 | O29: Stable
A30: TXN1077 | B30: 45735 | C30: April | D30: Harsh Vardhan | E30: 43 | F30: Delhi | G30: Business | H30: 149000 | I30: Investment | J30: 41000 | K30: Cheque | L30: 50000 | M30: 23000 | N30: 815 | O30: Excellent
A31: TXN1078 | B31: 45736 | C31: May | D31: Ankita Sen | E31: 30 | F31: Kolkata | G31: Salary | H31: 72000 | I31: Utilities | J31: 6300 | K31: UPI | L31: 14500 | M31: 3500 | N31: 735 | O31: Good
A32: TXN1079 | B32: 45737 | C32: June | D32: Rohan Sharma | E32: 28 | F32: Delhi | G32: Salary | H32: 65000 | I32: Transport | J32: 4800 | K32: Cash | L32: 10000 | M32: 4000 | N32: 712 | O32: Stable
A33: TXN1080 | B33: 45738 | C33: July | D33: Priya Roy | E33: 25 | F33: Kolkata | G33: Freelancing | H33: 50000 | I33: Shopping | J33: 8100 | K33: Card | L33: 6000 | N33: 689 | O33: Average
A34: TXN1081 | B34: 45739 | C34: August | D34: Abhishek Jain | E34: 40 | F34: Mumbai | H34: 137000 | I34: Rent | J34: 33000 | L34: 41000 | M34: 17000 | N34: 799 | O34: Excellent
A35: TXN1082 | B35: 45740 | C35: September | D35: Tania Das | E35: 31 | F35: Kolkata | G35: Salary | H35: 70000 | I35: Healthcare | J35: 4600 | K35: UPI | L35: 13000 | M35: 3000 | N35: 732 | O35: Good
A36: TXN1083 | B36: 45741 | C36: October | D36: Manish Roy | E36: 35 | F36: Delhi | G36: Salary | H36: 83000 | I36: Travel | J36: 10200 | K36: Card | L36: 18000 | M36: 9500 | N36: 747 | O36: Good
A37: TXN1084 | B37: 45742 | C37: November | D37: Sweta Kapoor | E37: 26 | F37: Pune | G37: Freelancing | H37: 53000 | I37: Entertainment | J37: 4100 | K37: Cash | L37: 7000 | N37: 694 | O37: Average
A38: TXN1085 | B38: 45743 | C38: December | D38: Kunal Verma | E38: 42 | F38: Ahmedabad | G38: Business | H38: 144000 | I38: Investment | J38: 37000 | K38: Cheque | L38: 46000 | M38: 21000 | N38: 810 | O38: Excellent
A39: TXN1086 | B39: 45744 | C39: January | D39: Megha Roy | E39: 29 | F39: Kolkata | G39: Salary | H39: 69000 | I39: Groceries | J39: 6200 | K39: UPI | L39: 12500 | M39: 3000 | N39: 728 | O39: Good
A40: TXN1087 | B40: 45745 | C40: February | D40: Rajat Das | E40: 33 | G40: Salary | H40: 78000 | I40: Rent | J40: 22000 | K40: Card | L40: 15000 | M40: 7000 | N40: 739 | O40: Good
...

Sheet Cleaning Tasks
A1: DATA CLEANING PROCESS
A2: Id | B2: Date | C2: Month | D2: Person Name | E2: Age | F2: City | G2: Income Source | H2: Monthly Income | I2: Expense Category | J2: Expense Amount | K2: Payment Method | L2: Savings | M2: Loan EMI | N2: Credit Score | O2: Financial Status | P2: City2 | Q2: Income Source2 | R2: Expense Category2 | S2: Loan EMI2 | T2: Payment Method2
A3: TXN1001 | B3: 45659 | C3: January | D3: Rahul Sen | E3: 29 | F3: Kolkata | G3: Salary | H3: 65000 | I3: Rent | J3: 18000 | K3: UPI | L3: 12000 | M3: 5000 | N3: 742 | O3: Stable | P3: =IF(COUNTBLANK(F3)=0,F3,"Unknown") -> Kolkata | Q3: =IF(COUNTBLANK(G3)=0,G3,"Unknown") -> Salary | R3: =IF(COUNTBLANK(I3)=0,I3,"Unknown") -> Rent | S3: =IF(COUNTBLANK(M3)=0,M3,0) -> 5000 | T3: =IF(COUNTBLANK(K3)=0,K3,"Cash/UPI") -> UPI
A4: TXN1002 | B4: 45660 | C4: February | D4: Priya Das | E4: 34 | F4: Mumbai | G4: Freelancing | H4: 72000 | I4: Groceries | J4: 6500 | K4: Card | L4: 15000 | N4: 788 | O4: Good | P4: =IF(COUNTBLANK(F4)=0,F4,"Unknown") -> Mumbai | Q4: =IF(COUNTBLANK(G4)=0,G4,"Unknown") -> Freelancing | R4: =IF(COUNTBLANK(I4)=0,I4,"Unknown") -> Groceries | S4: =IF(COUNTBLANK(M4)=0,M4,0) -> 0 | T4: =IF(COUNTBLANK(K4)=0,K4,"Cash/UPI") -> Card
A5: TXN1003 | B5: 45661 | C5: March | D5: Ankit Roy | E5: 26 | G5: Salary | H5: 54000 | J5: 3200 | K5: Cash | L5: 8000 | M5: 2500 | N5: 689 | O5: Average | P5: =IF(COUNTBLANK(F5)=0,F5,"Unknown") -> Unknown | Q5: =IF(COUNTBLANK(G5)=0,G5,"Unknown") -> Salary | R5: =IF(COUNTBLANK(I5)=0,I5,"Unknown") -> Unknown | S5: =IF(COUNTBLANK(M5)=0,M5,0) -> 2500 | T5: =IF(COUNTBLANK(K5)=0,K5,"Cash/UPI") -> Cash
A6: TXN1004 | B6: 45662 | C6: April | D6: Sneha Paul | E6: 31 | F6: Bangalore | G6: Business | H6: 98000 | I6: Utilities | J6: 5400 | K6: NetBanking | L6: 25000 | M6: 8000 | N6: 801 | O6: Excellent | P6: =IF(COUNTBLANK(F6)=0,F6,"Unknown") -> Bangalore | Q6: =IF(COUNTBLANK(G6)=0,G6,"Unknown") -> Business | R6: =IF(COUNTBLANK(I6)=0,I6,"Unknown") -> Utilities | S6: =IF(COUNTBLANK(M6)=0,M6,0) -> 8000 | T6: =IF(COUNTBLANK(K6)=0,K6,"Cash/UPI") -> NetBanking
A7: TXN1005 | B7: 45663 | C7: May | D7: Rohan Mitra | E7: 38 | F7: Hyderabad | G7: Salary | H7: 85000 | I7: Entertainment | J7: 7600 | K7: Card | L7: 10000 | M7: 12000 | N7: 655 | O7: Risky | P7: =IF(COUNTBLANK(F7)=0,F7,"Unknown") -> Hyderabad | Q7: =IF(COUNTBLANK(G7)=0,G7,"Unknown") -> Salary | R7: =IF(COUNTBLANK(I7)=0,I7,"Unknown") -> Entertainment | S7: =IF(COUNTBLANK(M7)=0,M7,0) -> 12000 | T7: =IF(COUNTBLANK(K7)=0,K7,"Cash/UPI") -> Card
A8: TXN1006 | B8: 45664 | C8: June | D8: Aditi Sharma | E8: 27 | F8: Pune | G8: =IF(COUNTBLANK(G3)=0,G3,"UKNOWN") -> Salary | H8: 61000 | I8: Healthcare | J8: 2400 | K8: UPI | L8: 17000 | N8: 771 | O8: Good | P8: =IF(COUNTBLANK(F8)=0,F8,"Unknown") -> Pune | Q8: =IF(COUNTBLANK(G8)=0,G8,"Unknown") -> Salary | R8: =IF(COUNTBLANK(I8)=0,I8,"Unknown") -> Healthcare | S8: =IF(COUNTBLANK(M8)=0,M8,0) -> 0 | T8: =IF(COUNTBLANK(K8)=0,K8,"Cash/UPI") -> UPI
A9: TXN1007 | B9: 45665 | C9: July | D9: Karan Singh | E9: 42 | F9: Chennai | G9: Business | H9: 120000 | I9: Rent | J9: 25000 | K9: Cheque | L9: 35000 | M9: 18000 | N9: 720 | O9: Stable | P9: =IF(COUNTBLANK(F9)=0,F9,"Unknown") -> Chennai | Q9: =IF(COUNTBLANK(G9)=0,G9,"Unknown") -> Business | R9: =IF(COUNTBLANK(I9)=0,I9,"Unknown") -> Rent | S9: =IF(COUNTBLANK(M9)=0,M9,0) -> 18000 | T9: =IF(COUNTBLANK(K9)=0,K9,"Cash/UPI") -> Cheque
A10: TXN1008 | B10: 45666 | C10: August | D10: Megha Dutta | E10: 24 | F10: Kolkata | G10: Internship | H10: 28000 | I10: Education | J10: 4500 | K10: UPI | L10: 5000 | N10: 690 | O10: Average | P10: =IF(COUNTBLANK(F10)=0,F10,"Unknown") -> Kolkata | Q10: =IF(COUNTBLANK(G10)=0,G10,"Unknown") -> Internship | R10: =IF(COUNTBLANK(I10)=0,I10,"Unknown") -> Education | S10: =IF(COUNTBLANK(M10)=0,M10,0) -> 0 | T10: =IF(COUNTBLANK(K10)=0,K10,"Cash/UPI") -> UPI
A11: TXN1009 | B11: 45667 | C11: September | D11: Arjun Nair | E11: 36 | F11: Kochi | G11: Salary | H11: 76000 | J11: 8200 | K11: Card | L11: 14000 | M11: 7000 | N11: 745 | O11: Stable | P11: =IF(COUNTBLANK(F11)=0,F11,"Unknown") -> Kochi | Q11: =IF(COUNTBLANK(G11)=0,G11,"Unknown") -> Salary | R11: =IF(COUNTBLANK(I11)=0,I11,"Unknown") -> Unknown | S11: =IF(COUNTBLANK(M11)=0,M11,0) -> 7000 | T11: =IF(COUNTBLANK(K11)=0,K11,"Cash/UPI") -> Card
A12: TXN1010 | B12: 45668 | C12: October | D12: Neha Kapoor | E12: 30 | F12: Jaipur | G12: Freelancing | H12: 68000 | I12: Shopping | J12: 9200 | K12: UPI | L12: 11000 | M12: 3000 | N12: 732 | O12: Good | P12: =IF(COUNTBLANK(F12)=0,F12,"Unknown") -> Jaipur | Q12: =IF(COUNTBLANK(G12)=0,G12,"Unknown") -> Freelancing | R12: =IF(COUNTBLANK(I12)=0,I12,"Unknown") -> Shopping | S12: =IF(COUNTBLANK(M12)=0,M12,0) -> 3000 | T12: =IF(COUNTBLANK(K12)=0,K12,"Cash/UPI") -> UPI
A13: TXN1011 | B13: 45669 | C13: November | D13: Vikram Bose | E13: 45 | F13: Kolkata | G13: Business | H13: 150000 | I13: Investment | J13: 35000 | K13: NetBanking | L13: 40000 | M13: 20000 | N13: 810 | O13: Excellent | P13: =IF(COUNTBLANK(F13)=0,F13,"Unknown") -> Kolkata | Q13: =IF(COUNTBLANK(G13)=0,G13,"Unknown") -> Business | R13: =IF(COUNTBLANK(I13)=0,I13,"Unknown") -> Investment | S13: =IF(COUNTBLANK(M13)=0,M13,0) -> 20000 | T13: =IF(COUNTBLANK(K13)=0,K13,"Cash/UPI") -> NetBanking
A14: TXN1012 | B14: 45670 | C14: December | D14: Isha Jain | E14: 28 | F14: Delhi | H14: 59000 | I14: Food | J14: 5800 | L14: 9000 | M14: 2500 | N14: 704 | O14: Stable | P14: =IF(COUNTBLANK(F14)=0,F14,"Unknown") -> Delhi | Q14: =IF(COUNTBLANK(G14)=0,G14,"Unknown") -> Unknown | R14: =IF(COUNTBLANK(I14)=0,I14,"Unknown") -> Food | S14: =IF(COUNTBLANK(M14)=0,M14,0) -> 2500 | T14: =IF(COUNTBLANK(K14)=0,K14,"Cash/UPI") -> Cash/UPI
A15: TXN1013 | B15: 45671 | C15: January | D15: Sourav Ghosh | E15: 33 | G15: Salary | H15: 71000 | I15: Rent | J15: 21000 | K15: UPI | L15: 13000 | M15: 6000 | N15: 740 | O15: Good | P15: =IF(COUNTBLANK(F15)=0,F15,"Unknown") -> Unknown | Q15: =IF(COUNTBLANK(G15)=0,G15,"Unknown") -> Salary | R15: =IF(COUNTBLANK(I15)=0,I15,"Unknown") -> Rent | S15: =IF(COUNTBLANK(M15)=0,M15,0) -> 6000 | T15: =IF(COUNTBLANK(K15)=0,K15,"Cash/UPI") -> UPI
A16: TXN1014 | B16: 45672 | C16: February | D16: Ritika Sen | E16: 25 | F16: Pune | G16: Freelancing | H16: 47000 | I16: Entertainment | J16: 4200 | K16: Card | L16: 7000 | N16: 681 | O16: Average | P16: =IF(COUNTBLANK(F16)=0,F16,"Unknown") -> Pune | Q16: =IF(COUNTBLANK(G16)=0,G16,"Unknown") -> Freelancing | R16: =IF(COUNTBLANK(I16)=0,I16,"Unknown") -> Entertainment | S16: =IF(COUNTBLANK(M16)=0,M16,0) -> 0 | T16: =IF(COUNTBLANK(K16)=0,K16,"Cash/UPI") -> Card
A17: TXN1015 | B17: 45673 | C17: March | D17: Abhishek Das | E17: 39 | F17: Bangalore | G17: Business | H17: 132000 | I17: Healthcare | J17: 6800 | K17: NetBanking | L17: 30000 | M17: 15000 | N17: 790 | O17: Excellent | P17: =IF(COUNTBLANK(F17)=0,F17,"Unknown") -> Bangalore | Q17: =IF(COUNTBLANK(G17)=0,G17,"Unknown") -> Business | R17: =IF(COUNTBLANK(I17)=0,I17,"Unknown") -> Healthcare | S17: =IF(COUNTBLANK(M17)=0,M17,0) -> 15000 | T17: =IF(COUNTBLANK(K17)=0,K17,"Cash/UPI") -> NetBanking
A18: TXN1016 | B18: 45674 | C18: April | D18: Nikita Roy | E18: 29 | F18: Delhi | G18: Salary | H18: 62000 | I18: Groceries | J18: 5900 | K18: UPI | L18: 12000 | M18: 3000 | N18: 725 | O18: Good | P18: =IF(COUNTBLANK(F18)=0,F18,"Unknown") -> Delhi | Q18: =IF(COUNTBLANK(G18)=0,G18,"Unknown") -> Salary | R18: =IF(COUNTBLANK(I18)=0,I18,"Unknown") -> Groceries | S18: =IF(COUNTBLANK(M18)=0,M18,0) -> 3000 | T18: =IF(COUNTBLANK(K18)=0,K18,"Cash/UPI") -> UPI
A19: TXN1017 | B19: 45675 | C19: May | D19: Manish Yadav | E19: 35 | F19: Mumbai | G19: Salary | H19: 81000 | I19: Transport | J19: 4100 | K19: Cash | L19: 16000 | M19: 9000 | N19: 710 | O19: Stable | P19: =IF(COUNTBLANK(F19)=0,F19,"Unknown") -> Mumbai | Q19: =IF(COUNTBLANK(G19)=0,G19,"Unknown") -> Salary | R19: =IF(COUNTBLANK(I19)=0,I19,"Unknown") -> Transport | S19: =IF(COUNTBLANK(M19)=0,M19,0) -> 9000 | T19: =IF(COUNTBLANK(K19)=0,K19,"Cash/UPI") -> Cash
A20: TXN1018 | B20: 45676 | C20: June | D20: Simran Kaur | E20: 27 | F20: Chandigarh | G20: Freelancing | H20: 56000 | J20: 9700 | K20: Card | L20: 8500 | N20: 699 | O20: Average | P20: =IF(COUNTBLANK(F20)=0,F20,"Unknown") -> Chandigarh | Q20: =IF(COUNTBLANK(G20)=0,G20,"Unknown") -> Freelancing | R20: =IF(COUNTBLANK(I20)=0,I20,"Unknown") -> Unknown | S20: =IF(COUNTBLANK(M20)=0,M20,0) -> 0 | T20: =IF(COUNTBLANK(K20)=0,K20,"Cash/UPI") -> Card
A21: TXN1019 | B21: 45677 | C21: July | D21: Raj Malhotra | E21: 41 | F21: Delhi | G21: Business | H21: 145000 | I21: Utilities | J21: 7800 | K21: Cheque | L21: 42000 | M21: 25000 | N21: 805 | O21: Excellent | P21: =IF(COUNTBLANK(F21)=0,F21,"Unknown") -> Delhi | Q21: =IF(COUNTBLANK(G21)=0,G21,"Unknown") -> Business | R21: =IF(COUNTBLANK(I21)=0,I21,"Unknown") -> Utilities | S21: =IF(COUNTBLANK(M21)=0,M21,0) -> 25000 | T21: =IF(COUNTBLANK(K21)=0,K21,"Cash/UPI") -> Cheque
A22: TXN1020 | B22: 45678 | C22: August | D22: Pooja Mehta | E22: 32 | F22: Ahmedabad | G22: Salary | H22: 69000 | I22: Food | J22: 6300 | K22: UPI | L22: 10000 | M22: 4500 | N22: 730 | O22: Good | P22: =IF(COUNTBLANK(F22)=0,F22,"Unknown") -> Ahmedabad | Q22: =IF(COUNTBLANK(G22)=0,G22,"Unknown") -> Salary | R22: =IF(COUNTBLANK(I22)=0,I22,"Unknown") -> Food | S22: =IF(COUNTBLANK(M22)=0,M22,0) -> 4500 | T22: =IF(COUNTBLANK(K22)=0,K22,"Cash/UPI") -> UPI
A23: TXN1021 | B23: 45679 | C23: September | D23: Deepak Kumar | E23: 37 | F23: Patna | G23: Salary | H23: 57000 | I23: Rent | J23: 16000 | K23: Cash | L23: 6000 | M23: 5500 | N23: 670 | O23: Risky | P23: =IF(COUNTBLANK(F23)=0,F23,"Unknown") -> Patna | Q23: =IF(COUNTBLANK(G23)=0,G23,"Unknown") -> Salary | R23: =IF(COUNTBLANK(I23)=0,I23,"Unknown") -> Rent | S23: =IF(COUNTBLANK(M23)=0,M23,0) -> 5500 | T23: =IF(COUNTBLANK(K23)=0,K23,"Cash/UPI") -> Cash
A24: TXN1022 | B24: 45680 | C24: October | D24: Tanvi Shah | E24: 26 | F24: Surat | G24: Freelancing | H24: 52000 | I24: Shopping | J24: 7600 | K24: Card | L24: 9000 | N24: 715 | O24: Stable | P24: =IF(COUNTBLANK(F24)=0,F24,"Unknown") -> Surat | Q24: =IF(COUNTBLANK(G24)=0,G24,"Unknown") -> Freelancing | R24: =IF(COUNTBLANK(I24)=0,I24,"Unknown") -> Shopping | S24: =IF(COUNTBLANK(M24)=0,M24,0) -> 0 | T24: =IF(COUNTBLANK(K24)=0,K24,"Cash/UPI") -> Card
A25: TXN1023 | B25: 45681 | C25: November | D25: Ritesh Verma | E25: 40 | H25: 125000 | I25: Investment | J25: 28000 | K25: NetBanking | L25: 37000 | M25: 12000 | N25: 798 | O25: Excellent | P25: =IF(COUNTBLANK(F25)=0,F25,"Unknown") -> Unknown | Q25: =IF(COUNTBLANK(G25)=0,G25,"Unknown") -> Unknown | R25: =IF(COUNTBLANK(I25)=0,I25,"Unknown") -> Investment | S25: =IF(COUNTBLANK(M25)=0,M25,0) -> 12000 | T25: =IF(COUNTBLANK(K25)=0,K25,"Cash/UPI") -> NetBanking
A26: TXN1024 | B26: 45682 | C26: December | D26: Ananya Ghosh | E26: 31 | F26: Kolkata | G26: Salary | H26: 74000 | I26: Education | J26: 5300 | K26: UPI | L26: 15000 | M26: 5000 | N26: 750 | O26: Good | P26: =IF(COUNTBLANK(F26)=0,F26,"Unknown") -> Kolkata | Q26: =IF(COUNTBLANK(G26)=0,G26,"Unknown") -> Salary | R26: =IF(COUNTBLANK(I26)=0,I26,"Unknown") -> Education | S26: =IF(COUNTBLANK(M26)=0,M26,0) -> 5000 | T26: =IF(COUNTBLANK(K26)=0,K26,"Cash/UPI") -> UPI
A27: TXN1025 | B27: 45683 | C27: January | D27: Kunal Sharma | E27: 28 | F27: Delhi | G27: Salary | H27: 63000 | J27: 8600 | K27: Card | L27: 11000 | M27: 3500 | N27: 721 | O27: Stable | P27: =IF(COUNTBLANK(F27)=0,F27,"Unknown") -> Delhi | Q27: =IF(COUNTBLANK(G27)=0,G27,"Unknown") -> Salary | R27: =IF(COUNTBLANK(I27)=0,I27,"Unknown") -> Unknown | S27: =IF(COUNTBLANK(M27)=0,M27,0) -> 3500 | T27: =IF(COUNTBLANK(K27)=0,K27,"Cash/UPI") -> Card
A28: TXN1075 | B28: 45733 | C28: February | D28: Amit Bose | E28: 36 | F28: Kolkata | G28: Salary | H28: 81000 | I28: Travel | J28: 9400 | K28: UPI | L28: 17000 | M28: 8500 | N28: 743 | O28: Good | P28: =IF(COUNTBLANK(F28)=0,F28,"Unknown") -> Kolkata | Q28: =IF(COUNTBLANK(G28)=0,G28,"Unknown") -> Salary | R28: =IF(COUNTBLANK(I28)=0,I28,"Unknown") -> Travel | S28: =IF(COUNTBLANK(M28)=0,M28,0) -> 8500 | T28: =IF(COUNTBLANK(K28)=0,K28,"Cash/UPI") -> UPI
A29: TXN1076 | B29: 45734 | C29: March | D29: Sonia Jain | E29: 27 | F29: Pune | G29: Freelancing | H29: 55000 | I29: Food | J29: 5200 | K29: Card | L29: 8000 | N29: 701 | O29: Stable | P29: =IF(COUNTBLANK(F29)=0,F29,"Unknown") -> Pune | Q29: =IF(COUNTBLANK(G29)=0,G29,"Unknown") -> Freelancing | R29: =IF(COUNTBLANK(I29)=0,I29,"Unknown") -> Food | S29: =IF(COUNTBLANK(M29)=0,M29,0) -> 0 | T29: =IF(COUNTBLANK(K29)=0,K29,"Cash/UPI") -> Card
A30: TXN1077 | B30: 45735 | C30: April | D30: Harsh Vardhan | E30: 43 | F30: Delhi | G30: Business | H30: 149000 | I30: Investment | J30: 41000 | K30: Cheque | L30: 50000 | M30: 23000 | N30: 815 | O30: Excellent | P30: =IF(COUNTBLANK(F30)=0,F30,"Unknown") -> Delhi | Q30: =IF(COUNTBLANK(G30)=0,G30,"Unknown") -> Business | R30: =IF(COUNTBLANK(I30)=0,I30,"Unknown") -> Investment | S30: =IF(COUNTBLANK(M30)=0,M30,0) -> 23000 | T30: =IF(COUNTBLANK(K30)=0,K30,"Cash/UPI") -> Cheque
A31: TXN1078 | B31: 45736 | C31: May | D31: Ankita Sen | E31: 30 | F31: Kolkata | G31: Salary | H31: 72000 | I31: Utilities | J31: 6300 | K31: UPI | L31: 14500 | M31: 3500 | N31: 735 | O31: Good | P31: =IF(COUNTBLANK(F31)=0,F31,"Unknown") -> Kolkata | Q31: =IF(COUNTBLANK(G31)=0,G31,"Unknown") -> Salary | R31: =IF(COUNTBLANK(I31)=0,I31,"Unknown") -> Utilities | S31: =IF(COUNTBLANK(M31)=0,M31,0) -> 3500 | T31: =IF(COUNTBLANK(K31)=0,K31,"Cash/UPI") -> UPI
A32: TXN1079 | B32: 45737 | C32: June | D32: Rohan Sharma | E32: 28 | F32: Delhi | G32: Salary | H32: 65000 | I32: Transport | J32: 4800 | K32: Cash | L32: 10000 | M32: 4000 | N32: 712 | O32: Stable | P32: =IF(COUNTBLANK(F32)=0,F32,"Unknown") -> Delhi | Q32: =IF(COUNTBLANK(G32)=0,G32,"Unknown") -> Salary | R32: =IF(COUNTBLANK(I32)=0,I32,"Unknown") -> Transport | S32: =IF(COUNTBLANK(M32)=0,M32,0) -> 4000 | T32: =IF(COUNTBLANK(K32)=0,K32,"Cash/UPI") -> Cash
A33: TXN1080 | B33: 45738 | C33: July | D33: Priya Roy | E33: 25 | F33: Kolkata | G33: Freelancing | H33: 50000 | I33: Shopping | J33: 8100 | K33: Card | L33: 6000 | N33: 689 | O33: Average | P33: =IF(COUNTBLANK(F33)=0,F33,"Unknown") -> Kolkata | Q33: =IF(COUNTBLANK(G33)=0,G33,"Unknown") -> Freelancing | R33: =IF(COUNTBLANK(I33)=0,I33,"Unknown") -> Shopping | S33: =IF(COUNTBLANK(M33)=0,M33,0) -> 0 | T33: =IF(COUNTBLANK(K33)=0,K33,"Cash/UPI") -> Card
A34: TXN1081 | B34: 45739 | C34: August | D34: Abhishek Jain | E34: 40 | F34: Mumbai | H34: 137000 | I34: Rent | J34: 33000 | L34: 41000 | M34: 17000 | N34: 799 | O34: Excellent | P34: =IF(COUNTBLANK(F34)=0,F34,"Unknown") -> Mumbai | Q34: =IF(COUNTBLANK(G34)=0,G34,"Unknown") -> Unknown | R34: =IF(COUNTBLANK(I34)=0,I34,"Unknown") -> Rent | S34: =IF(COUNTBLANK(M34)=0,M34,0) -> 17000 | T34: =IF(COUNTBLANK(K34)=0,K34,"Cash/UPI") -> Cash/UPI
A35: TXN1082 | B35: 45740 | C35: September | D35: Tania Das | E35: 31 | F35: Kolkata | G35: Salary | H35: 70000 | I35: Healthcare | J35: 4600 | K35: UPI | L35: 13000 | M35: 3000 | N35: 732 | O35: Good | P35: =IF(COUNTBLANK(F35)=0,F35,"Unknown") -> Kolkata | Q35: =IF(COUNTBLANK(G35)=0,G35,"Unknown") -> Salary | R35: =IF(COUNTBLANK(I35)=0,I35,"Unknown") -> Healthcare | S35: =IF(COUNTBLANK(M35)=0,M35,0) -> 3000 | T35: =IF(COUNTBLANK(K35)=0,K35,"Cash/UPI") -> UPI
A36: TXN1083 | B36: 45741 | C36: October | D36: Manish Roy | E36: 35 | F36: Delhi | G36: Salary | H36: 83000 | I36: Travel | J36: 10200 | K36: Card | L36: 18000 | M36: 9500 | N36: 747 | O36: Good | P36: =IF(COUNTBLANK(F36)=0,F36,"Unknown") -> Delhi | Q36: =IF(COUNTBLANK(G36)=0,G36,"Unknown") -> Salary | R36: =IF(COUNTBLANK(I36)=0,I36,"Unknown") -> Travel | S36: =IF(COUNTBLANK(M36)=0,M36,0) -> 9500 | T36: =IF(COUNTBLANK(K36)=0,K36,"Cash/UPI") -> Card
A37: TXN1084 | B37: 45742 | C37: November | D37: Sweta Kapoor | E37: 26 | F37: Pune | G37: Freelancing | H37: 53000 | I37: Entertainment | J37: 4100 | K37: Cash | L37: 7000 | N37: 694 | O37: Average | P37: =IF(COUNTBLANK(F37)=0,F37,"Unknown") -> Pune | Q37: =IF(COUNTBLANK(G37)=0,G37,"Unknown") -> Freelancing | R37: =IF(COUNTBLANK(I37)=0,I37,"Unknown") -> Entertainment | S37: =IF(COUNTBLANK(M37)=0,M37,0) -> 0 | T37: =IF(COUNTBLANK(K37)=0,K37,"Cash/UPI") -> Cash
A38: TXN1085 | B38: 45743 | C38: December | D38: Kunal Verma | E38: 42 | F38: Ahmedabad | G38: Business | H38: 144000 | I38: Investment | J38: 37000 | K38: Cheque | L38: 46000 | M38: 21000 | N38: 810 | O38: Excellent | P38: =IF(COUNTBLANK(F38)=0,F38,"Unknown") -> Ahmedabad | Q38: =IF(COUNTBLANK(G38)=0,G38,"Unknown") -> Business | R38: =IF(COUNTBLANK(I38)=0,I38,"Unknown") -> Investment | S38: =IF(COUNTBLANK(M38)=0,M38,0) -> 21000 | T38: =IF(COUNTBLANK(K38)=0,K38,"Cash/UPI") -> Cheque
A39: TXN1086 | B39: 45744 | C39: January | D39: Megha Roy | E39: 29 | F39: Kolkata | G39: Salary | H39: 69000 | I39: Groceries | J39: 6200 | K39: UPI | L39: 12500 | M39: 3000 | N39: 728 | O39: Good | P39: =IF(COUNTBLANK(F39)=0,F39,"Unknown") -> Kolkata | Q39: =IF(COUNTBLANK(G39)=0,G39,"Unknown") -> Salary | R39: =IF(COUNTBLANK(I39)=0,I39,"Unknown") -> Groceries | S39: =IF(COUNTBLANK(M39)=0,M39,0) -> 3000 | T39: =IF(COUNTBLANK(K39)=0,K39,"Cash/UPI") -> UPI
A40: TXN1087 | B40: 45745 | C40: February | D40: Rajat Das | E40: 33 | G40: Salary | H40: 78000 | I40: Rent | J40: 22000 | K40: Card | L40: 15000 | M40: 7000 | N40: 739 | O40: Good | P40: =IF(COUNTBLANK(F40)=0,F40,"Unknown") -> Unknown | Q40: =IF(COUNTBLANK(G40)=0,G40,"Unknown") -> Salary | R40: =IF(COUNTBLANK(I40)=0,I40,"Unknown") -> Rent | S40: =IF(COUNTBLANK(M40)=0,M40,0) -> 7000 | T40: =IF(COUNTBLANK(K40)=0,K40,"Cash/UPI") -> Card
...

Sheet Cleaned Data
A1: CLEANED DATA
A2: Id | B2: Date | C2: Month | D2: Person Name | E2: Age | F2: City | G2: Income Source | H2: Monthly Income | I2: Expense Category | J2: Expense Amount | K2: Payment Method | L2: Savings | M2: Loan EMI | N2: Credit Score | O2: Financial Status
A3: TXN1001 | B3: 45659 | C3: January | D3: Rahul Sen | E3: 29 | F3: =_xlfn.XLOOKUP(D3,'Cleaning Tasks'!D3:D100,'Cleaning Tasks'!P3:P100) -> Kolkata | G3: =_xlfn.XLOOKUP(D3,'Cleaned Data'!D3:D100,'Cleaning Tasks'!Q3:Q100) -> Salary | H3: =_xlfn.XLOOKUP(D3,'Cleaning Tasks'!D3:D100,'Cleaning Tasks'!H3:H100) -> 65000 | I3: =_xlfn.XLOOKUP(D3,'Cleaning Tasks'!D3:D100,'Cleaning Tasks'!R3:R100) -> Rent | J3: 18000 | K3: UPI | L3: 12000 | M3: =_xlfn.XLOOKUP(D3,'Cleaning Tasks'!D3:D100,'Cleaning Tasks'!S3:S100) -> 5000 | N3: 742 | O3: Stable
A4: TXN1002 | B4: 45660 | C4: February | D4: Priya Das | E4: 34 | F4: =_xlfn.XLOOKUP(D4,'Cleaning Tasks'!D4:D101,'Cleaning Tasks'!P4:P101) -> Mumbai | G4: =_xlfn.XLOOKUP(D4,'Cleaned Data'!D4:D101,'Cleaning Tasks'!Q4:Q101) -> Freelancing | H4: =_xlfn.XLOOKUP(D4,'Cleaning Tasks'!D4:D101,'Cleaning Tasks'!H4:H101) -> 72000 | I4: =_xlfn.XLOOKUP(D4,'Cleaning Tasks'!D4:D101,'Cleaning Tasks'!R4:R101) -> Groceries | J4: 6500 | K4: Card | L4: 15000 | M4: =_xlfn.XLOOKUP(D4,'Cleaning Tasks'!D4:D101,'Cleaning Tasks'!S4:S101) -> 0 | N4: 788 | O4: Good
A5: TXN1003 | B5: 45661 | C5: March | D5: Ankit Roy | E5: 26 | F5: =_xlfn.XLOOKUP(D5,'Cleaning Tasks'!D5:D102,'Cleaning Tasks'!P5:P102) -> Unknown | G5: =_xlfn.XLOOKUP(D5,'Cleaned Data'!D5:D102,'Cleaning Tasks'!Q5:Q102) -> Salary | H5: =_xlfn.XLOOKUP(D5,'Cleaning Tasks'!D5:D102,'Cleaning Tasks'!H5:H102) -> 54000 | I5: =_xlfn.XLOOKUP(D5,'Cleaning Tasks'!D5:D102,'Cleaning Tasks'!R5:R102) -> Unknown | J5: 3200 | K5: Cash | L5: 8000 | M5: =_xlfn.XLOOKUP(D5,'Cleaning Tasks'!D5:D102,'Cleaning Tasks'!S5:S102) -> 2500 | N5: 689 | O5: Average
A6: TXN1004 | B6: 45662 | C6: April | D6: Sneha Paul | E6: 31 | F6: =_xlfn.XLOOKUP(D6,'Cleaning Tasks'!D6:D103,'Cleaning Tasks'!P6:P103) -> Bangalore | G6: =_xlfn.XLOOKUP(D6,'Cleaned Data'!D6:D103,'Cleaning Tasks'!Q6:Q103) -> Business | H6: =_xlfn.XLOOKUP(D6,'Cleaning Tasks'!D6:D103,'Cleaning Tasks'!H6:H103) -> 98000 | I6: =_xlfn.XLOOKUP(D6,'Cleaning Tasks'!D6:D103,'Cleaning Tasks'!R6:R103) -> Utilities | J6: 5400 | K6: NetBanking | L6: 25000 | M6: =_xlfn.XLOOKUP(D6,'Cleaning Tasks'!D6:D103,'Cleaning Tasks'!S6:S103) -> 8000 | N6: 801 | O6: Excellent
A7: TXN1005 | B7: 45663 | C7: May | D7: Rohan Mitra | E7: 38 | F7: =_xlfn.XLOOKUP(D7,'Cleaning Tasks'!D7:D104,'Cleaning Tasks'!P7:P104) -> Hyderabad | G7: =_xlfn.XLOOKUP(D7,'Cleaned Data'!D7:D104,'Cleaning Tasks'!Q7:Q104) -> Salary | H7: =_xlfn.XLOOKUP(D7,'Cleaning Tasks'!D7:D104,'Cleaning Tasks'!H7:H104) -> 85000 | I7: =_xlfn.XLOOKUP(D7,'Cleaning Tasks'!D7:D104,'Cleaning Tasks'!R7:R104) -> Entertainment | J7: 7600 | K7: Card | L7: 10000 | M7: =_xlfn.XLOOKUP(D7,'Cleaning Tasks'!D7:D104,'Cleaning Tasks'!S7:S104) -> 12000 | N7: 655 | O7: Risky
A8: TXN1006 | B8: 45664 | C8: June | D8: Aditi Sharma | E8: 27 | F8: =_xlfn.XLOOKUP(D8,'Cleaning Tasks'!D8:D105,'Cleaning Tasks'!P8:P105) -> Pune | G8: =_xlfn.XLOOKUP(D8,'Cleaned Data'!D8:D105,'Cleaning Tasks'!Q8:Q105) -> Salary | H8: =_xlfn.XLOOKUP(D8,'Cleaning Tasks'!D8:D105,'Cleaning Tasks'!H8:H105) -> 61000 | I8: =_xlfn.XLOOKUP(D8,'Cleaning Tasks'!D8:D105,'Cleaning Tasks'!R8:R105) -> Healthcare | J8: 2400 | K8: UPI | L8: 17000 | M8: =_xlfn.XLOOKUP(D8,'Cleaning Tasks'!D8:D105,'Cleaning Tasks'!S8:S105) -> 0 | N8: 771 | O8: Good
A9: TXN1007 | B9: 45665 | C9: July | D9: Karan Singh | E9: 42 | F9: =_xlfn.XLOOKUP(D9,'Cleaning Tasks'!D9:D106,'Cleaning Tasks'!P9:P106) -> Chennai | G9: =_xlfn.XLOOKUP(D9,'Cleaned Data'!D9:D106,'Cleaning Tasks'!Q9:Q106) -> Business | H9: =_xlfn.XLOOKUP(D9,'Cleaning Tasks'!D9:D106,'Cleaning Tasks'!H9:H106) -> 120000 | I9: =_xlfn.XLOOKUP(D9,'Cleaning Tasks'!D9:D106,'Cleaning Tasks'!R9:R106) -> Rent | J9: 25000 | K9: Cheque | L9: 35000 | M9: =_xlfn.XLOOKUP(D9,'Cleaning Tasks'!D9:D106,'Cleaning Tasks'!S9:S106) -> 18000 | N9: 720 | O9: Stable
A10: TXN1008 | B10: 45666 | C10: August | D10: Megha Dutta | E10: 24 | F10: =_xlfn.XLOOKUP(D10,'Cleaning Tasks'!D10:D107,'Cleaning Tasks'!P10:P107) -> Kolkata | G10: =_xlfn.XLOOKUP(D10,'Cleaned Data'!D10:D107,'Cleaning Tasks'!Q10:Q107) -> Internship | H10: =_xlfn.XLOOKUP(D10,'Cleaning Tasks'!D10:D107,'Cleaning Tasks'!H10:H107) -> 28000 | I10: =_xlfn.XLOOKUP(D10,'Cleaning Tasks'!D10:D107,'Cleaning Tasks'!R10:R107) -> Education | J10: 4500 | K10: UPI | L10: 5000 | M10: =_xlfn.XLOOKUP(D10,'Cleaning Tasks'!D10:D107,'Cleaning Tasks'!S10:S107) -> 0 | N10: 690 | O10: Average
A11: TXN1009 | B11: 45667 | C11: September | D11: Arjun Nair | E11: 36 | F11: =_xlfn.XLOOKUP(D11,'Cleaning Tasks'!D11:D108,'Cleaning Tasks'!P11:P108) -> Kochi | G11: =_xlfn.XLOOKUP(D11,'Cleaned Data'!D11:D108,'Cleaning Tasks'!Q11:Q108) -> Salary | H11: =_xlfn.XLOOKUP(D11,'Cleaning Tasks'!D11:D108,'Cleaning Tasks'!H11:H108) -> 76000 | I11: =_xlfn.XLOOKUP(D11,'Cleaning Tasks'!D11:D108,'Cleaning Tasks'!R11:R108) -> Unknown | J11: 8200 | K11: Card | L11: 14000 | M11: =_xlfn.XLOOKUP(D11,'Cleaning Tasks'!D11:D108,'Cleaning Tasks'!S11:S108) -> 7000 | N11: 745 | O11: Stable
A12: TXN1010 | B12: 45668 | C12: October | D12: Neha Kapoor | E12: 30 | F12: =_xlfn.XLOOKUP(D12,'Cleaning Tasks'!D12:D109,'Cleaning Tasks'!P12:P109) -> Jaipur | G12: =_xlfn.XLOOKUP(D12,'Cleaned Data'!D12:D109,'Cleaning Tasks'!Q12:Q109) -> Freelancing | H12: =_xlfn.XLOOKUP(D12,'Cleaning Tasks'!D12:D109,'Cleaning Tasks'!H12:H109) -> 68000 | I12: =_xlfn.XLOOKUP(D12,'Cleaning Tasks'!D12:D109,'Cleaning Tasks'!R12:R109) -> Shopping | J12: 9200 | K12: UPI | L12: 11000 | M12: =_xlfn.XLOOKUP(D12,'Cleaning Tasks'!D12:D109,'Cleaning Tasks'!S12:S109) -> 3000 | N12: 732 | O12: Good
A13: TXN1011 | B13: 45669 | C13: November | D13: Vikram Bose | E13: 45 | F13: =_xlfn.XLOOKUP(D13,'Cleaning Tasks'!D13:D110,'Cleaning Tasks'!P13:P110) -> Kolkata | G13: =_xlfn.XLOOKUP(D13,'Cleaned Data'!D13:D110,'Cleaning Tasks'!Q13:Q110) -> Business | H13: =_xlfn.XLOOKUP(D13,'Cleaning Tasks'!D13:D110,'Cleaning Tasks'!H13:H110) -> 150000 | I13: =_xlfn.XLOOKUP(D13,'Cleaning Tasks'!D13:D110,'Cleaning Tasks'!R13:R110) -> Investment | J13: 35000 | K13: NetBanking | L13: 40000 | M13: =_xlfn.XLOOKUP(D13,'Cleaning Tasks'!D13:D110,'Cleaning Tasks'!S13:S110) -> 20000 | N13: 810 | O13: Excellent
A14: TXN1012 | B14: 45670 | C14: December | D14: Isha Jain | E14: 28 | F14: =_xlfn.XLOOKUP(D14,'Cleaning Tasks'!D14:D111,'Cleaning Tasks'!P14:P111) -> Delhi | G14: =_xlfn.XLOOKUP(D14,'Cleaned Data'!D14:D111,'Cleaning Tasks'!Q14:Q111) -> Unknown | H14: =_xlfn.XLOOKUP(D14,'Cleaning Tasks'!D14:D111,'Cleaning Tasks'!H14:H111) -> 59000 | I14: =_xlfn.XLOOKUP(D14,'Cleaning Tasks'!D14:D111,'Cleaning Tasks'!R14:R111) -> Food | J14: 5800 | K14: Cash/UPI | L14: 9000 | M14: =_xlfn.XLOOKUP(D14,'Cleaning Tasks'!D14:D111,'Cleaning Tasks'!S14:S111) -> 2500 | N14: 704 | O14: Stable
... A100: TXN1072 | B100: 45730 | C100: February | D100: Payal Roy | E100: 24 | F100: =_xlfn.XLOOKUP(D100,'Cleaning Tasks'!D100:D197,'Cleaning Tasks'!P100:P197) -> Unknown | G100: =_xlfn.XLOOKUP(D100,'Cleaned Data'!D100:D197,'Cleaning Tasks'!Q100:Q197) -> Unknown | H100: =_xlfn.XLOOKUP(D100,'Cleaning Tasks'!D100:D197,'Cleaning Tasks'!H100:H197) -> 32000 | I100: =_xlfn.XLOOKUP(D100,'Cleaning Tasks'!D100:D197,'Cleaning Tasks'!R100:R197) -> Unknown | J100: 3900 | K100: Cash/UPI | L100: 3500 | M100: =_xlfn.XLOOKUP(D100,'Cleaning Tasks'!D100:D197,'Cleaning Tasks'!S100:S197) -> 0 | N100: 678 | O100: Average

Sheet Income Analysis
A1: 📈 INCOME ANALYSIS — SOURCE & MONTHLY BREAKDOWN | N1: Go to Welcome Page
A2: ▌ MONTHLY INCOME SUMMARY
A3: Income Source | B3: January | C3: February | D3: March | E3: April | F3: May | G3: June | H3: July | I3: August | J3: September | K3: October | L3: November | M3: December | N3: TOTAL
A4: {=_xlfn.UNIQUE('Cleaned Data'!G3:G100)} -> Salary | B4: =SUMIFS('Cleaned Data'!$H$3:$H$100,'Cleaned Data'!$G$3:$G$100,$A4,'Cleaned Data'!$C$3:$C$100,B$3) -> 605000 | C4: =SUMIFS('Cleaned Data'!$H$3:$H$100,'Cleaned Data'!$G$3:$G$100,$A4,'Cleaned Data'!$C$3:$C$100,C$3) -> 246000 | D4: =SUMIFS('Cleaned Data'!$H$3:$H$100,'Cleaned Data'!$G$3:$G$100,$A4,'Cleaned Data'!$C$3:$C$100,D$3) -> 124000 | E4: =SUMIFS('Cleaned Data'!$H$3:$H$100,'Cleaned Data'!$G$3:$G$100,$A4,'Cleaned Data'!$C$3:$C$100,E$3) -> 284000 | F4: =SUMIFS('Cleaned Data'!$H$3:$H$100,'Cleaned Data'!$G$3:$G$100,$A4,'Cleaned Data'!$C$3:$C$100,F$3) -> 373000 | G4: =SUMIFS('Cleaned Data'!$H$3:$H$100,'Cleaned Data'!$G$3:$G$100,$A4,'Cleaned Data'!$C$3:$C$100,G$3) -> 212000 | H4: =SUMIFS('Cleaned Data'!$H$3:$H$100,'Cleaned Data'!$G$3:$G$100,$A4,'Cleaned Data'!$C$3:$C$100,H$3) -> 159000 | I4: =SUMIFS('Cleaned Data'!$H$3:$H$100,'Cleaned Data'!$G$3:$G$100,$A4,'Cleaned Data'!$C$3:$C$100,I$3) -> 222000 | ... M4: =SUMIFS('Cleaned Data'!$H$3:$H$100,'Cleaned Data'!$G$3:$G$100,$A4,'Cleaned Data'!$C$3:$C$100,M$3) -> 280000 | N4: =SUM(B4:M4) -> 3235000
A5: Freelancing | B5: =SUMIFS('Cleaned Data'!$H$3:$H$100,'Cleaned Data'!$G$3:$G$100,$A5,'Cleaned Data'!$C$3:$C$100,B$3) -> 0 | C5: =SUMIFS('Cleaned Data'!$H$3:$H$100,'Cleaned Data'!$G$3:$G$100,$A5,'Cleaned Data'!$C$3:$C$100,C$3) -> 168000 | D5: =SUMIFS('Cleaned Data'!$H$3:$H$100,'Cleaned Data'!$G$3:$G$100,$A5,'Cleaned Data'!$C$3:$C$100,D$3) -> 109000 | E5: =SUMIFS('Cleaned Data'!$H$3:$H$100,'Cleaned Data'!$G$3:$G$100,$A5,'Cleaned Data'!$C$3:$C$100,E$3) -> 0 | F5: =SUMIFS('Cleaned Data'!$H$3:$H$100,'Cleaned Data'!$G$3:$G$100,$A5,'Cleaned Data'!$C$3:$C$100,F$3) -> 106000 | G5: =SUMIFS('Cleaned Data'!$H$3:$H$100,'Cleaned Data'!$G$3:$G$100,$A5,'Cleaned Data'!$C$3:$C$100,G$3) -> 110000 | H5: =SUMIFS('Cleaned Data'!$H$3:$H$100,'Cleaned Data'!$G$3:$G$100,$A5,'Cleaned Data'!$C$3:$C$100,H$3) -> 155000 | I5: =SUMIFS('Cleaned Data'!$H$3:$H$100,'Cleaned Data'!$G$3:$G$100,$A5,'Cleaned Data'!$C$3:$C$100,I$3) -> 0 | ... M5: =SUMIFS('Cleaned Data'!$H$3:$H$100,'Cleaned Data'!$G$3:$G$100,$A5,'Cleaned Data'!$C$3:$C$100,M$3) -> 64000 | N5: =SUM(B5:M5) -> 992000
A6: Business | B6: =SUMIFS('Cleaned Data'!$H$3:$H$100,'Cleaned Data'!$G$3:$G$100,$A6,'Cleaned Data'!$C$3:$C$100,B$3) -> 0 | C6: =SUMIFS('Cleaned Data'!$H$3:$H$100,'Cleaned Data'!$G$3:$G$100,$A6,'Cleaned Data'!$C$3:$C$100,C$3) -> 155000 | D6: =SUMIFS('Cleaned Data'!$H$3:$H$100,'Cleaned Data'!$G$3:$G$100,$A6,'Cleaned Data'!$C$3:$C$100,D$3) -> 278000 | E6: =SUMIFS('Cleaned Data'!$H$3:$H$100,'Cleaned Data'!$G$3:$G$100,$A6,'Cleaned Data'!$C$3:$C$100,E$3) -> 533000 | F6: =SUMIFS('Cleaned Data'!$H$3:$H$100,'Cleaned Data'!$G$3:$G$100,$A6,'Cleaned Data'!$C$3:$C$100,F$3) -> 0 | G6: =SUMIFS('Cleaned Data'!$H$3:$H$100,'Cleaned Data'!$G$3:$G$100,$A6,'Cleaned Data'!$C$3:$C$100,G$3) -> 252000 | H6: =SUMIFS('Cleaned Data'!$H$3:$H$100,'Cleaned Data'!$G$3:$G$100,$A6,'Cleaned Data'!$C$3:$C$100,H$3) -> 417000 | I6: =SUMIFS('Cleaned Data'!$H$3:$H$100,'Cleaned Data'!$G$3:$G$100,$A6,'Cleaned Data'!$C$3:$C$100,I$3) -> 139000 | ... M6: =SUMIFS('Cleaned Data'!$H$3:$H$100,'Cleaned Data'!$G$3:$G$100,$A6,'Cleaned Data'!$C$3:$C$100,M$3) -> 292000 | N6: =SUM(B6:M6) -> 2487000
A7: Internship | B7: =SUMIFS('Cleaned Data'!$H$3:$H$100,'Cleaned Data'!$G$3:$G$100,$A7,'Cleaned Data'!$C$3:$C$100,B$3) -> 0 | C7: =SUMIFS('Cleaned Data'!$H$3:$H$100,'Cleaned Data'!$G$3:$G$100,$A7,'Cleaned Data'!$C$3:$C$100,C$3) -> 0 | D7: =SUMIFS('Cleaned Data'!$H$3:$H$100,'Cleaned Data'!$G$3:$G$100,$A7,'Cleaned Data'!$C$3:$C$100,D$3) -> 59000 | E7: =SUMIFS('Cleaned Data'!$H$3:$H$100,'Cleaned Data'!$G$3:$G$100,$A7,'Cleaned Data'!$C$3:$C$100,E$3) -> 0 | F7: =SUMIFS('Cleaned Data'!$H$3:$H$100,'Cleaned Data'!$G$3:$G$100,$A7,'Cleaned Data'!$C$3:$C$100,F$3) -> 0 | G7: =SUMIFS('Cleaned Data'!$H$3:$H$100,'Cleaned Data'!$G$3:$G$100,$A7,'Cleaned Data'!$C$3:$C$100,G$3) -> 0 | H7: =SUMIFS('Cleaned Data'!$H$3:$H$100,'Cleaned Data'!$G$3:$G$100,$A7,'Cleaned Data'!$C$3:$C$100,H$3) -> 0 | I7: =SUMIFS('Cleaned Data'!$H$3:$H$100,'Cleaned Data'!$G$3:$G$100,$A7,'Cleaned Data'!$C$3:$C$100,I$3) -> 59000 | ... M7: =SUMIFS('Cleaned Data'!$H$3:$H$100,'Cleaned Data'!$G$3:$G$100,$A7,'Cleaned Data'!$C$3:$C$100,M$3) -> 0 | N7: =SUM(B7:M7) -> 176000
A8: Unknown | B8: =SUMIFS('Cleaned Data'!$H$3:$H$100,'Cleaned Data'!$G$3:$G$100,$A8,'Cleaned Data'!$C$3:$C$100,B$3) -> 0 | C8: =SUMIFS('Cleaned Data'!$H$3:$H$100,'Cleaned Data'!$G$3:$G$100,$A8,'Cleaned Data'!$C$3:$C$100,C$3) -> 112000 | D8: =SUMIFS('Cleaned Data'!$H$3:$H$100,'Cleaned Data'!$G$3:$G$100,$A8,'Cleaned Data'!$C$3:$C$100,D$3) -> 0 | E8: =SUMIFS('Cleaned Data'!$H$3:$H$100,'Cleaned Data'!$G$3:$G$100,$A8,'Cleaned Data'!$C$3:$C$100,E$3) -> 0 | F8: =SUMIFS('Cleaned Data'!$H$3:$H$100,'Cleaned Data'!$G$3:$G$100,$A8,'Cleaned Data'!$C$3:$C$100,F$3) -> 73000 | G8: =SUMIFS('Cleaned Data'!$H$3:$H$100,'Cleaned Data'!$G$3:$G$100,$A8,'Cleaned Data'!$C$3:$C$100,G$3) -> 0 | H8: =SUMIFS('Cleaned Data'!$H$3:$H$100,'Cleaned Data'!$G$3:$G$100,$A8,'Cleaned Data'!$C$3:$C$100,H$3) -> 0 | I8: =SUMIFS('Cleaned Data'!$H$3:$H$100,'Cleaned Data'!$G$3:$G$100,$A8,'Cleaned Data'!$C$3:$C$100,I$3) -> 210000 | ... M8: =SUMIFS('Cleaned Data'!$H$3:$H$100,'Cleaned Data'!$G$3:$G$100,$A8,'Cleaned Data'!$C$3:$C$100,M$3) -> 59000 | N8: =SUM(B8:M8) -> 916000
A9: Salary | B9: =SUMIFS('Cleaned Data'!$H$3:$H$100,'Cleaned Data'!$G$3:$G$100,$A9,'Cleaned Data'!$C$3:$C$100,B$3) -> 0 | C9: =SUMIFS('Cleaned Data'!$H$3:$H$100,'Cleaned Data'!$G$3:$G$100,$A9,'Cleaned Data'!$C$3:$C$100,C$3) -> 0 | D9: =SUMIFS('Cleaned Data'!$H$3:$H$100,'Cleaned Data'!$G$3:$G$100,$A9,'Cleaned Data'!$C$3:$C$100,D$3) -> 0 | E9: =SUMIFS('Cleaned Data'!$H$3:$H$100,'Cleaned Data'!$G$3:$G$100,$A9,'Cleaned Data'!$C$3:$C$100,E$3) -> 0 | F9: =SUMIFS('Cleaned Data'!$H$3:$H$100,'Cleaned Data'!$G$3:$G$100,$A9,'Cleaned Data'!$C$3:$C$100,F$3) -> 0 | G9: =SUMIFS('Cleaned Data'!$H$3:$H$100,'Cleaned Data'!$G$3:$G$100,$A9,'Cleaned Data'!$C$3:$C$100,G$3) -> 65000 | H9: =SUMIFS('Cleaned Data'!$H$3:$H$100,'Cleaned Data'!$G$3:$G$100,$A9,'Cleaned Data'!$C$3:$C$100,H$3) -> 0 | I9: =SUMIFS('Cleaned Data'!$H$3:$H$100,'Cleaned Data'!$G$3:$G$100,$A9,'Cleaned Data'!$C$3:$C$100,I$3) -> 0 | ... M9: =SUMIFS('Cleaned Data'!$H$3:$H$100,'Cleaned Data'!$G$3:$G$100,$A9,'Cleaned Data'!$C$3:$C$100,M$3) -> 0 | N9: =SUM(B9:M9) -> 65000
A10: GRAND TOTAL | B10: =SUM(B4:B9) -> 605000 | C10: =SUM(C4:C9) -> 681000 | D10: =SUM(D4:D9) -> 570000 | E10: =SUM(E4:E9) -> 817000 | F10: =SUM(F4:F9) -> 552000 | G10: =SUM(G4:G9) -> 639000 | H10: =SUM(H4:H9) -> 731000 | I10: =SUM(I4:I9) -> 630000 | ... N10: =SUM(N4:N9) -> 7871000
Q12: i

Sheet Expense Analysis
A1: 💸 EXPENSE ANALYSIS — CATEGORY BREAKDOWN | O1: Go to Welcome Page
A3: Expense Category | B3: January | C3: February | D3: March | E3: April | F3: May | G3: June | H3: July | I3: August | J3: September | K3: October | L3: November | M3: December | N3: TOTAL | O3: % OF TOTAL
A4: {=_xlfn.UNIQUE('Cleaned Data'!I3:I100)} -> Rent | B4: =SUMIFS('Cleaned Data'!$J:$J,'Cleaned Data'!$I:$I,$A4,'Cleaned Data'!$C:$C,B$3) -> 78000 | C4: =SUMIFS('Cleaned Data'!$J:$J,'Cleaned Data'!$I:$I,$A4,'Cleaned Data'!$C:$C,C$3) -> 56000 | D4: =SUMIFS('Cleaned Data'!$J:$J,'Cleaned Data'!$I:$I,$A4,'Cleaned Data'!$C:$C,D$3) -> 0 | E4: =SUMIFS('Cleaned Data'!$J:$J,'Cleaned Data'!$I:$I,$A4,'Cleaned Data'!$C:$C,E$3) -> 0 | F4: =SUMIFS('Cleaned Data'!$J:$J,'Cleaned Data'!$I:$I,$A4,'Cleaned Data'!$C:$C,F$3) -> 0 | G4: =SUMIFS('Cleaned Data'!$J:$J,'Cleaned Data'!$I:$I,$A4,'Cleaned Data'!$C:$C,G$3) -> 46000 | H4: =SUMIFS('Cleaned Data'!$J:$J,'Cleaned Data'!$I:$I,$A4,'Cleaned Data'!$C:$C,H$3) -> 61000 | I4: =SUMIFS('Cleaned Data'!$J:$J,'Cleaned Data'!$I:$I,$A4,'Cleaned Data'!$C:$C,I$3) -> 50500 | ... M4: =SUMIFS('Cleaned Data'!$J:$J,'Cleaned Data'!$I:$I,$A4,'Cleaned Data'!$C:$C,M$3) -> 0 | N4: =SUM(B4:M4) -> 327000 | O4: =N4/$N$16 -> 0.28686727
A5: Groceries | B5: =SUMIFS('Cleaned Data'!$J:$J,'Cleaned Data'!$I:$I,$A5,'Cleaned Data'!$C:$C,B$3) -> 6200 | C5: =SUMIFS('Cleaned Data'!$J:$J,'Cleaned Data'!$I:$I,$A5,'Cleaned Data'!$C:$C,C$3) -> 6500 | D5: =SUMIFS('Cleaned Data'!$J:$J,'Cleaned Data'!$I:$I,$A5,'Cleaned Data'!$C:$C,D$3) -> 0 | E5: =SUMIFS('Cleaned Data'!$J:$J,'Cleaned Data'!$I:$I,$A5,'Cleaned Data'!$C:$C,E$3) -> 5900 | F5: =SUMIFS('Cleaned Data'!$J:$J,'Cleaned Data'!$I:$I,$A5,'Cleaned Data'!$C:$C,F$3) -> 0 | G5: =SUMIFS('Cleaned Data'!$J:$J,'Cleaned Data'!$I:$I,$A5,'Cleaned Data'!$C:$C,G$3) -> 0 | H5: =SUMIFS('Cleaned Data'!$J:$J,'Cleaned Data'!$I:$I,$A5,'Cleaned Data'!$C:$C,H$3) -> 6800 | I5: =SUMIFS('Cleaned Data'!$J:$J,'Cleaned Data'!$I:$I,$A5,'Cleaned Data'!$C:$C,I$3) -> 0 | ... M5: =SUMIFS('Cleaned Data'!$J:$J,'Cleaned Data'!$I:$I,$A5,'Cleaned Data'!$C:$C,M$3) -> 13100 | N5: =SUM(B5:M5) -> 38500 | O5: =N5/$N$16 -> 0.033774893
A6: Unknown | B6: =SUMIFS('Cleaned Data'!$J:$J,'Cleaned Data'!$I:$I,$A6,'Cleaned Data'!$C:$C,B$3) -> 8600 | C6: =SUMIFS('Cleaned Data'!$J:$J,'Cleaned Data'!$I:$I,$A6,'Cleaned Data'!$C:$C,C$3) -> 3900 | D6: =SUMIFS('Cleaned Data'!$J:$J,'Cleaned Data'!$I:$I,$A6,'Cleaned Data'!$C:$C,D$3) -> 3200 | E6: =SUMIFS('Cleaned Data'!$J:$J,'Cleaned Data'!$I:$I,$A6,'Cleaned Data'!$C:$C,E$3) -> 0 | F6: =SUMIFS('Cleaned Data'!$J:$J,'Cleaned Data'!$I:$I,$A6,'Cleaned Data'!$C:$C,F$3) -> 10800 | G6: =SUMIFS('Cleaned Data'!$J:$J,'Cleaned Data'!$I:$I,$A6,'Cleaned Data'!$C:$C,G$3) -> 19400 | H6: =SUMIFS('Cleaned Data'!$J:$J,'Cleaned Data'!$I:$I,$A6,'Cleaned Data'!$C:$C,H$3) -> 0 | I6: =SUMIFS('Cleaned Data'!$J:$J,'Cleaned Data'!$I:$I,$A6,'Cleaned Data'!$C:$C,I$3) -> 0 | ... M6: =SUMIFS('Cleaned Data'!$J:$J,'Cleaned Data'!$I:$I,$A6,'Cleaned Data'!$C:$C,M$3) -> 0 | N6: =SUM(B6:M6) -> 58400 | O6: =N6/$N$16 -> 0.051232564
A7: Utilities | B7: =SUMIFS('Cleaned Data'!$J:$J,'Cleaned Data'!$I:$I,$A7,'Cleaned Data'!$C:$C,B$3) -> 6100 | C7: =SUMIFS('Cleaned Data'!$J:$J,'Cleaned Data'!$I:$I,$A7,'Cleaned Data'!$C:$C,C$3) -> 0 | D7: =SUMIFS('Cleaned Data'!$J:$J,'Cleaned Data'!$I:$I,$A7,'Cleaned Data'!$C:$C,D$3) -> 0 | E7: =SUMIFS('Cleaned Data'!$J:$J,'Cleaned Data'!$I:$I,$A7,'Cleaned Data'!$C:$C,E$3) -> 5400 | F7: =SUMIFS('Cleaned Data'!$J:$J,'Cleaned Data'!$I:$I,$A7,'Cleaned Data'!$C:$C,F$3) -> 6300 | G7: =SUMIFS('Cleaned Data'!$J:$J,'Cleaned Data'!$I:$I,$A7,'Cleaned Data'!$C:$C,G$3) -> 0 | H7: =SUMIFS('Cleaned Data'!$J:$J,'Cleaned Data'!$I:$I,$A7,'Cleaned Data'!$C:$C,H$3) -> 15000 | I7: =SUMIFS('Cleaned Data'!$J:$J,'Cleaned Data'!$I:$I,$A7,'Cleaned Data'!$C:$C,I$3) -> 0 | ... M7: =SUMIFS('Cleaned Data'!$J:$J,'Cleaned Data'!$I:$I,$A7,'Cleaned Data'!$C:$C,M$3) -> 0 | N7: =SUM(B7:M7) -> 44800 | O7: =N7/$N$16 -> 0.039301693
A8: Entertainment | B8: =SUMIFS('Cleaned Data'!$J:$J,'Cleaned Data'!$I:$I,$A8,'Cleaned Data'!$C:$C,B$3) -> 0 | C8: =SUMIFS('Cleaned Data'!$J:$J,'Cleaned Data'!$I:$I,$A8,'Cleaned Data'!$C:$C,C$3) -> 8900 | D8: =SUMIFS('Cleaned Data'!$J:$J,'Cleaned Data'!$I:$I,$A8,'Cleaned Data'!$C:$C,D$3) -> 8900 | E8: =SUMIFS('Cleaned Data'!$J:$J,'Cleaned Data'!$I:$I,$A8,'Cleaned Data'!$C:$C,E$3) -> 0 | F8: =SUMIFS('Cleaned Data'!$J:$J,'Cleaned Data'!$I:$I,$A8,'Cleaned Data'!$C:$C,F$3) -> 7600 | G8: =SUMIFS('Cleaned Data'!$J:$J,'Cleaned Data'!$I:$I,$A8,'Cleaned Data'!$C:$C,G$3) -> 0 | H8: =SUMIFS('Cleaned Data'!$J:$J,'Cleaned Data'!$I:$I,$A8,'Cleaned Data'!$C:$C,H$3) -> 4500 | I8: =SUMIFS('Cleaned Data'!$J:$J,'Cleaned Data'!$I:$I,$A8,'Cleaned Data'!$C:$C,I$3) -> 0 | ... M8: =SUMIFS('Cleaned Data'!$J:$J,'Cleaned Data'!$I:$I,$A8,'Cleaned Data'!$C:$C,M$3) -> 0 | N8: =SUM(B8:M8) -> 34000 | O8: =N8/$N$16 -> 0.029827178
A9: Healthcare | B9: =SUMIFS('Cleaned Data'!$J:$J,'Cleaned Data'!$I:$I,$A9,'Cleaned Data'!$C:$C,B$3) -> 0 | C9: =SUMIFS('Cleaned Data'!$J:$J,'Cleaned Data'!$I:$I,$A9,'Cleaned Data'!$C:$C,C$3) -> 0 | D9: =SUMIFS('Cleaned Data'!$J:$J,'Cleaned Data'!$I:$I,$A9,'Cleaned Data'!$C:$C,D$3) -> 6800 | E9: =SUMIFS('Cleaned Data'!$J:$J,'Cleaned Data'!$I:$I,$A9,'Cleaned Data'!$C:$C,E$3) -> 24600 | F9: =SUMIFS('Cleaned Data'!$J:$J,'Cleaned Data'!$I:$I,$A9,'Cleaned Data'!$C:$C,F$3) -> 0 | G9: =SUMIFS('Cleaned Data'!$J:$J,'Cleaned Data'!$I:$I,$A9,'Cleaned Data'!$C:$C,G$3) -> 2400 | H9: =SUMIFS('Cleaned Data'!$J:$J,'Cleaned Data'!$I:$I,$A9,'Cleaned Data'!$C:$C,H$3) -> 0 | I9: =SUMIFS('Cleaned Data'!$J:$J,'Cleaned Data'!$I:$I,$A9,'Cleaned Data'!$C:$C,I$3) -> 0 | ... M9: =SUMIFS('Cleaned Data'!$J:$J,'Cleaned Data'!$I:$I,$A9,'Cleaned Data'!$C:$C,M$3) -> 8300 | N9: =SUM(B9:M9) -> 56000 | O9: =N9/$N$16 -> 0.049127116
A10: Education | B10: =SUMIFS('Cleaned Data'!$J:$J,'Cleaned Data'!$I:$I,$A10,'Cleaned Data'!$C:$C,B$3) -> 6200 | C10: =SUMIFS('Cleaned Data'!$J:$J,'Cleaned Data'!$I:$I,$A10,'Cleaned Data'!$C:$C,C$3) -> 0 | D10: =SUMIFS('Cleaned Data'!$J:$J,'Cleaned Data'!$I:$I,$A10,'Cleaned Data'!$C:$C,D$3) -> 0 | E10: =SUMIFS('Cleaned Data'!$J:$J,'Cleaned Data'!$I:$I,$A10,'Cleaned Data'!$C:$C,E$3) -> 0 | F10: =SUMIFS('Cleaned Data'!$J:$J,'Cleaned Data'!$I:$I,$A10,'Cleaned Data'!$C:$C,F$3) -> 0 | G10: =SUMIFS('Cleaned Data'!$J:$J,'Cleaned Data'!$I:$I,$A10,'Cleaned Data'!$C:$C,G$3) -> 0 | H10: =SUMIFS('Cleaned Data'!$J:$J,'Cleaned Data'!$I:$I,$A10,'Cleaned Data'!$C:$C,H$3) -> 0 | I10: =SUMIFS('Cleaned Data'!$J:$J,'Cleaned Data'!$I:$I,$A10,'Cleaned Data'!$C:$C,I$3) -> 8300 | ... M10: =SUMIFS('Cleaned Data'!$J:$J,'Cleaned Data'!$I:$I,$A10,'Cleaned Data'!$C:$C,M$3) -> 5300 | N10: =SUM(B10:M10) -> 23700 | O10: =N10/$N$16 -> 0.020791297
A11: Shopping | B11: =SUMIFS('Cleaned Data'!$J:$J,'Cleaned Data'!$I:$I,$A11,'Cleaned Data'!$C:$C,B$3) -> 7400 | C11: =SUMIFS('Cleaned Data'!$J:$J,'Cleaned Data'!$I:$I,$A11,'Cleaned Data'!$C:$C,C$3) -> 0 | D11: =SUMIFS('Cleaned Data'!$J:$J,'Cleaned Data'!$I:$I,$A11,'Cleaned Data'!$C:$C,D$3) -> 0 | E11: =SUMIFS('Cleaned Data'!$J:$J,'Cleaned Data'!$I:$I,$A11,'Cleaned Data'!$C:$C,E$3) -> 0 | F11: =SUMIFS('Cleaned Data'!$J:$J,'Cleaned Data'!$I:$I,$A11,'Cleaned Data'!$C:$C,F$3) -> 16200 | G11: =SUMIFS('Cleaned Data'!$J:$J,'Cleaned Data'!$I:$I,$A11,'Cleaned Data'!$C:$C,G$3) -> 0 | H11: =SUMIFS('Cleaned Data'!$J:$J,'Cleaned Data'!$I:$I,$A11,'Cleaned Data'!$C:$C,H$3) -> 16000 | I11: =SUMIFS('Cleaned Data'!$J:$J,'Cleaned Data'!$I:$I,$A11,'Cleaned Data'!$C:$C,I$3) -> 8400 | ... M11: =SUMIFS('Cleaned Data'!$J:$J,'Cleaned Data'!$I:$I,$A11,'Cleaned Data'!$C:$C,M$3) -> 7200 | N11: =SUM(B11:M11) -> 78900 | O11: =N11/$N$16 -> 0.069216598
A12: Investment | B12: =SUMIFS('Cleaned Data'!$J:$J,'Cleaned Data'!$I:$I,$A12,'Cleaned Data'!$C:$C,B$3) -> 0 | C12: =SUMIFS('Cleaned Data'!$J:$J,'Cleaned Data'!$I:$I,$A12,'Cleaned Data'!$C:$C,C$3) -> 0 | D12: =SUMIFS('Cleaned Data'!$J:$J,'Cleaned Data'!$I:$I,$A12,'Cleaned Data'!$C:$C,D$3) -> 39000 | E12: =SUMIFS('Cleaned Data'!$J:$J,'Cleaned Data'!$I:$I,$A12,'Cleaned Data'!$C:$C,E$3) -> 41000 | F12: =SUMIFS('Cleaned Data'!$J:$J,'Cleaned Data'!$I:$I,$A12,'Cleaned Data'!$C:$C,F$3) -> 0 | G12: =SUMIFS('Cleaned Data'!$J:$J,'Cleaned Data'!$I:$I,$A12,'Cleaned Data'!$C:$C,G$3) -> 31000 | H12: =SUMIFS('Cleaned Data'!$J:$J,'Cleaned Data'!$I:$I,$A12,'Cleaned Data'!$C:$C,H$3) -> 0 | I12: =SUMIFS('Cleaned Data'!$J:$J,'Cleaned Data'!$I:$I,$A12,'Cleaned Data'!$C:$C,I$3) -> 35000 | ... M12: =SUMIFS('Cleaned Data'!$J:$J,'Cleaned Data'!$I:$I,$A12,'Cleaned Data'!$C:$C,M$3) -> 37000 | N12: =SUM(B12:M12) -> 344000 | O12: =N12/$N$16 -> 0.30178086
A13: Food | B13: =SUMIFS('Cleaned Data'!$J:$J,'Cleaned Data'!$I:$I,$A13,'Cleaned Data'!$C:$C,B$3) -> 0 | C13: =SUMIFS('Cleaned Data'!$J:$J,'Cleaned Data'!$I:$I,$A13,'Cleaned Data'!$C:$C,C$3) -> 0 | D13: =SUMIFS('Cleaned Data'!$J:$J,'Cleaned Data'!$I:$I,$A13,'Cleaned Data'!$C:$C,D$3) -> 13800 | E13: =SUMIFS('Cleaned Data'!$J:$J,'Cleaned Data'!$I:$I,$A13,'Cleaned Data'!$C:$C,E$3) -> 0 | F13: =SUMIFS('Cleaned Data'!$J:$J,'Cleaned Data'!$I:$I,$A13,'Cleaned Data'!$C:$C,F$3) -> 0 | G13: =SUMIFS('Cleaned Data'!$J:$J,'Cleaned Data'!$I:$I,$A13,'Cleaned Data'!$C:$C,G$3) -> 5900 | H13: =SUMIFS('Cleaned Data'!$J:$J,'Cleaned Data'!$I:$I,$A13,'Cleaned Data'!$C:$C,H$3) -> 0 | I13: =SUMIFS('Cleaned Data'!$J:$J,'Cleaned Data'!$I:$I,$A13,'Cleaned Data'!$C:$C,I$3) -> 6300 | ... M13: =SUMIFS('Cleaned Data'!$J:$J,'Cleaned Data'!$I:$I,$A13,'Cleaned Data'!$C:$C,M$3) -> 11400 | N13: =SUM(B13:M13) -> 41300 | O13: =N13/$N$16 -> 0.036231248
A14: Transport | B14: =SUMIFS('Cleaned Data'!$J:$J,'Cleaned Data'!$I:$I,$A14,'Cleaned Data'!$C:$C,B$3) -> 0 | C14: =SUMIFS('Cleaned Data'!$J:$J,'Cleaned Data'!$I:$I,$A14,'Cleaned Data'!$C:$C,C$3) -> 4300 | D14: =SUMIFS('Cleaned Data'!$J:$J,'Cleaned Data'!$I:$I,$A14,'Cleaned Data'!$C:$C,D$3) -> 0 | E14: =SUMIFS('Cleaned Data'!$J:$J,'Cleaned Data'!$I:$I,$A14,'Cleaned Data'!$C:$C,E$3) -> 4800 | F14: =SUMIFS('Cleaned Data'!$J:$J,'Cleaned Data'!$I:$I,$A14,'Cleaned Data'!$C:$C,F$3) -> 9200 | G14: =SUMIFS('Cleaned Data'!$J:$J,'Cleaned Data'!$I:$I,$A14,'Cleaned Data'!$C:$C,G$3) -> 4800 | H14: =SUMIFS('Cleaned Data'!$J:$J,'Cleaned Data'!$I:$I,$A14,'Cleaned Data'!$C:$C,H$3) -> 0 | I14: =SUMIFS('Cleaned Data'!$J:$J,'Cleaned Data'!$I:$I,$A14,'Cleaned Data'!$C:$C,I$3) -> 0 | ... M14: =SUMIFS('Cleaned Data'!$J:$J,'Cleaned Data'!$I:$I,$A14,'Cleaned Data'!$C:$C,M$3) -> 0 | N14: =SUM(B14:M14) -> 23100 | O14: =N14/$N$16 -> 0.020264936
A15: Travel | B15: =SUMIFS('Cleaned Data'!$J:$J,'Cleaned Data'!$I:$I,$A15,'Cleaned Data'!$C:$C,B$3) -> 0 | C15: =SUMIFS('Cleaned Data'!$J:$J,'Cleaned Data'!$I:$I,$A15,'Cleaned Data'!$C:$C,C$3) -> 19500 | D15: =SUMIFS('Cleaned Data'!$J:$J,'Cleaned Data'!$I:$I,$A15,'Cleaned Data'!$C:$C,D$3) -> 0 | E15: =SUMIFS('Cleaned Data'!$J:$J,'Cleaned Data'!$I:$I,$A15,'Cleaned Data'!$C:$C,E$3) -> 0 | F15: =SUMIFS('Cleaned Data'!$J:$J,'Cleaned Data'!$I:$I,$A15,'Cleaned Data'!$C:$C,F$3) -> 0 | G15: =SUMIFS('Cleaned Data'!$J:$J,'Cleaned Data'!$I:$I,$A15,'Cleaned Data'!$C:$C,G$3) -> 0 | H15: =SUMIFS('Cleaned Data'!$J:$J,'Cleaned Data'!$I:$I,$A15,'Cleaned Data'!$C:$C,H$3) -> 0 | I15: =SUMIFS('Cleaned Data'!$J:$J,'Cleaned Data'!$I:$I,$A15,'Cleaned Data'!$C:$C,I$3) -> 10400 | ... M15: =SUMIFS('Cleaned Data'!$J:$J,'Cleaned Data'!$I:$I,$A15,'Cleaned Data'!$C:$C,M$3) -> 0 | N15: =SUM(B15:M15) -> 70200 | O15: =N15/$N$16 -> 0.06158435
A16: TOTAL | B16: =SUM(B4:B15) -> 112500 | C16: =SUM(C4:C15) -> 99100 | D16: =SUM(D4:D15) -> 71700 | E16: =SUM(E4:E15) -> 81700 | F16: =SUM(F4:F15) -> 50100 | G16: =SUM(G4:G15) -> 109500 | H16: =SUM(H4:H15) -> 103300 | I16: =SUM(I4:I15) -> 118900 | ... N16: =SUM(N4:N15) -> 1139900 | O16: =N16/$N$16 -> 1

Sheet Budget Analysis
A1: 🏦 BUDGET ANALYSIS — PLANNED vs ACTUAL SPENDING
A2: ▌ SET YOUR BUDGET TARGETS BELOW (Blue = Input Cells — change freely)
A3: Expense Category | B3: Monthly Budget (₹) | C3: Actual (₹) | D3: Variance (₹) | E3: Var % | F3: Status
A4: Investment | B4: 412800 | C4: =SUMIF('Cleaned Data'!I3:I100,'Budget Analysis'!A4,'Cleaned Data'!J3:J100) -> 344000 | D4: =B4-C4 -> 68800 | E4: =IF(B4=0,0,(B4-C4)/B4) -> 0.16666667 | F4: =IF(D4>=0,"✅ Under Budget","⚠️ Over Budget") -> ✅ Under Budget
A5: Rent | B5: 362400 | C5: =SUMIF('Cleaned Data'!I4:I101,'Budget Analysis'!A5,'Cleaned Data'!J4:J101) -> 309000 | D5: =B5-C5 -> 53400 | E5: =IF(B5=0,0,(B5-C5)/B5) -> 0.14735099 | F5: =IF(D5>=0,"✅ Under Budget","⚠️ Over Budget") -> ✅ Under Budget
A6: Shopping | B6: 94700 | C6: =SUMIF('Cleaned Data'!I5:I102,'Budget Analysis'!A6,'Cleaned Data'!J5:J102) -> 78900 | D6: =B6-C6 -> 15800 | E6: =IF(B6=0,0,(B6-C6)/B6) -> 0.16684266 | F6: =IF(D6>=0,"✅ Under Budget","⚠️ Over Budget") -> ✅ Under Budget
A7: Travel | B7: 60000 | C7: =SUMIF('Cleaned Data'!I6:I103,'Budget Analysis'!A7,'Cleaned Data'!J6:J103) -> 70200 | D7: =B7-C7 -> -10200 | E7: =IF(B7=0,0,(B7-C7)/B7) -> -0.17 | F7: =IF(D7>=0,"✅ Under Budget","⚠️ Over Budget") -> ⚠️ Over Budget
A8: Unknown | B8: 70100 | C8: =SUMIF('Cleaned Data'!I7:I104,'Budget Analysis'!A8,'Cleaned Data'!J7:J104) -> 55200 | D8: =B8-C8 -> 14900 | E8: =IF(B8=0,0,(B8-C8)/B8) -> 0.2125535 | F8: =IF(D8>=0,"✅ Under Budget","⚠️ Over Budget") -> ✅ Under Budget
A9: Healthcare | B9: 67200 | C9: =SUMIF('Cleaned Data'!I8:I105,'Budget Analysis'!A9,'Cleaned Data'!J8:J105) -> 56000 | D9: =B9-C9 -> 11200 | E9: =IF(B9=0,0,(B9-C9)/B9) -> 0.16666667 | F9: =IF(D9>=0,"✅ Under Budget","⚠️ Over Budget") -> ✅ Under Budget
A10: Utilities | B10: 35000 | C10: =SUMIF('Cleaned Data'!I9:I106,'Budget Analysis'!A10,'Cleaned Data'!J9:J106) -> 39400 | D10: =B10-C10 -> -4400 | E10: =IF(B10=0,0,(B10-C10)/B10) -> -0.12571429 | F10: =IF(D10>=0,"✅ Under Budget","⚠️ Over Budget") -> ⚠️ Over Budget
A11: Food | B11: 49600 | C11: =SUMIF('Cleaned Data'!I10:I107,'Budget Analysis'!A11,'Cleaned Data'!J10:J107) -> 41300 | D11: =B11-C11 -> 8300 | E11: =IF(B11=0,0,(B11-C11)/B11) -> 0.16733871 | F11: =IF(D11>=0,"✅ Under Budget","⚠️ Over Budget") -> ✅ Under Budget
A12: Groceries | B12: 46200 | C12: =SUMIF('Cleaned Data'!I11:I108,'Budget Analysis'!A12,'Cleaned Data'!J11:J108) -> 32000 | D12: =B12-C12 -> 14200 | E12: =IF(B12=0,0,(B12-C12)/B12) -> 0.30735931 | F12: =IF(D12>=0,"✅ Under Budget","⚠️ Over Budget") -> ✅ Under Budget
A13: Entertainment | B13: 20000 | C13: =SUMIF('Cleaned Data'!I12:I109,'Budget Analysis'!A13,'Cleaned Data'!J12:J109) -> 26400 | D13: =B13-C13 -> -6400 | E13: =IF(B13=0,0,(B13-C13)/B13) -> -0.32 | F13: =IF(D13>=0,"✅ Under Budget","⚠️ Over Budget") -> ⚠️ Over Budget
A14: Education | B14: 28400 | C14: =SUMIF('Cleaned Data'!I13:I110,'Budget Analysis'!A14,'Cleaned Data'!J13:J110) -> 19200 | D14: =B14-C14 -> 9200 | E14: =IF(B14=0,0,(B14-C14)/B14) -> 0.32394366 | F14: =IF(D14>=0,"✅ Under Budget","⚠️ Over Budget") -> ✅ Under Budget
A15: Transport | B15: 27700 | C15: =SUMIF('Cleaned Data'!I14:I111,'Budget Analysis'!A15,'Cleaned Data'!J14:J111) -> 23100 | D15: =B15-C15 -> 4600 | E15: =IF(B15=0,0,(B15-C15)/B15) -> 0.16606498 | F15: =IF(D15>=0,"✅ Under Budget","⚠️ Over Budget") -> ✅ Under Budget
A16: TOTAL | B16: =SUM(B4:B15) -> 1274100 | C16: =SUM(C4:C15) -> 1094700 | D16: =SUM(D4:D15) -> 179400 | E16: =IF(B16=0,0,(B16-C16)/B16) -> 0.14080527

Sheet Pivot Analysis
A1: PIVOT ANALYSIS | L1: Go to Welcome Page
A3: Month | B3: Total Income | C3: Total Expense | D3: Total Savings | E3: EMI | F3: Net Surplus | H3: Expense Category | I3: Amount | K3: Income Source | L3: Total Income
A4: January | B4: 605000 | C4: 112500 | D4: 106700 | E4: 45300 | F4: =B4-(C4+D4+E4) -> 340500 | H4: Investment | I4: 344000 | K4: Salary | L4: 3235000
A5: February | B5: 681000 | C5: 99100 | D5: 148000 | E5: 63000 | F5: =B5-(C5+D5+E5) -> 370900 | H5: Rent | I5: 302000 | K5: Business | L5: 2487000
A6: March | B6: 570000 | C6: 71700 | D6: 120200 | E6: 42000 | F6: =B6-(C6+D6+E6) -> 336100 | H6: Shopping | I6: 78900 | K6: Freelancing | L6: 992000
A7: April | B7: 817000 | C7: 81700 | D7: 220000 | E7: 73000 | F7: =B7-(C7+D7+E7) -> 442300 | H7: Travel | I7: 70200 | K7: Unknown | L7: 916000
A8: May | B8: 552000 | C8: 50100 | D8: 90500 | E8: 37000 | F8: =B8-(C8+D8+E8) -> 374400 | H8: Unknown | I8: 58400 | K8: Internship | L8: 176000
A9: June | B9: 639000 | C9: 109500 | D9: 141500 | E9: 50000 | F9: =B9-(C9+D9+E9) -> 338000 | H9: Healthcare | I9: 56000 | K9: Salary | L9: 65000
A10: July | B10: 731000 | C10: 103300 | D10: 180500 | E10: 81000 | F10: =B10-(C10+D10+E10) -> 366200 | H10: Utilities | I10: 44800
A11: August | B11: 630000 | C11: 118900 | D11: 145500 | E11: 60000 | F11: =B11-(C11+D11+E11) -> 305600 | H11: Food | I11: 41300
A12: September | B12: 661000 | C12: 95000 | D12: 142000 | E12: 61000 | F12: =B12-(C12+D12+E12) -> 363000 | H12: Groceries | I12: 38500
A13: October | B13: 465000 | C13: 67500 | D13: 73500 | E13: 38000 | F13: =B13-(C13+D13+E13) -> 286000 | H13: Entertainment | I13: 34000
A14: November | B14: 825000 | C14: 148300 | D14: 211000 | E14: 84000 | F14: =B14-(C14+D14+E14) -> 381700 | H14: Education | I14: 23700
A15: December | B15: 695000 | C15: 82300 | D15: 167500 | E15: 61500 | F15: =B15-(C15+D15+E15) -> 383700 | H15: Transport | I15: 23100
A16: TOTAL | B16: =SUM(B4:B15) -> 7871000 | C16: =SUM(C4:C15) -> 1139900 | D16: =SUM(D4:D15) -> 1746900 | E16: =SUM(E4:E15) -> 695800 | F16: =SUM(F4:F15) -> 4288400

Sheet Final Dashboard
B2: 💰 PERSONAL FINANCE & BUDGET PLANNER | EXECUTIVE DASHBOARD | N2: Go to Welcome page
B3: Real-time KPI Tracker · 100 Transactions · Multiple Cities · FY 2024–25
B4: ▌ KEY PERFORMANCE INDICATORS
B6: 📈 TOTAL INCOME | F6: 📉 TOTAL EXPENSES | J6: 🏦 TOTAL SAVINGS
B7: ='Income Analysis'!N10 -> 7871000 | F7: ='Pivot Analysis'!C16+'Pivot Analysis'!E16 -> 1835700 | J7: ='Pivot Analysis'!D16 -> 1746900
B8: Across All Sources | F8: All Categories | J8: Net Accumulated
B10: 🏠 LOAN EMI | F10: ⭐ AVG CREDIT SCORE | J10: 💹 SAVINGS RATE
B11: ='Pivot Analysis'!E16 -> 695800 | F11: =AVERAGE('Cleaned Data'!N3:N100) -> 736.55102 | J11: =((B7-F7)/B7) -> 0.76677678
B12: Total EMI Paid | F12: Portfolio Average | J12: Income → Savings
B14: ⚠️ EXPENSE RATIO | F14: 📊 TRANSACTIONS | J14: 👤 AVG INCOME
B15: =(F7/B7) -> 0.23322322 | F15: =COUNTA('Cleaned Data'!A3:A100) -> 98 | J15: =B7/F15 -> 80316.327
B16: Income Spent | F16: Total Records | J16: Per Person
B18: ▌ INTERACTIVE ANALYSIS — MONTHLY INCOME vs EXPENSE vs SAVINGS
I38: ▌ FINANCIAL STATUS DISTRIBUTION
I39: Status | L39: Count
I40: ● Excellent | L40: =COUNTIF('Cleaned Data'!O3:O100,"Excellent") -> 21
I41: ● Good | L41: =COUNTIF('Cleaned Data'!O3:O100,"Good") -> 34
I42: ● Stable | L42: =COUNTIF('Cleaned Data'!O3:O100,"Stable") -> 21
I43: ● Average | L43: =COUNTIF('Cleaned Data'!O3:O100,"Average") -> 19
I44: ● Risky | L44: =COUNTIF('Cleaned Data'!O3:O100,"Risky") -> 3
I47: ▌ TOP CITIES — TOTAL SAVINGS (₹)
I48: City | L48: Total Savings (₹)
I49: Kolkata | L49: 353900
I50: Delhi | L50: 340500
I51: Ahmedabad | L51: 215000
I52: Bangalore | L52: 191000
I53: Mumbai | L53: 182000
I54: Unknown | L54: 135500
I55: Chennai | L55: 80000
I56: Patna | L56: 61000
B57: Dashboard auto-calculates from Cleaned Data sheet | Presented by Abhijit Roy & Aakash Nath | © 2025 Personal Finance Planner
